# C++异常处理

## 异常的语法

:::details `捕获全部的异常`

```c++
   try
    {
        // 可能抛出异常的代码。
        // throw 异常对象;
    }
    catch (...)
    {
        // 不管什么异常，都在这里统一处理。
    }
```

:::



:::details `捕获指定的异常`

```c++
   try
    {
        // 可能抛出异常的代码。
        // throw 异常对象;
    }
    catch (exception1 e)
    {
        // 发生exception1异常时的处理代码。
    }
    catch (exception2 e)
    {
       // 发生exception2异常时的处理代码。
    }
```

在try语句块中，如果没有发生异常，执行完try语句块中的代码后，将继续执行try语句块之后的代码；



如果发生了异常，用throw抛出异常对象，异常对象的类型决定了应该匹配到哪个catch语句块，如果没有匹配到catch语句块，程序将调用abort()函数中止。



如果try语句块中用throw抛出异常对象，并且匹配到了catch语句块，执行完catch语句块中的代码后，将继续执行catch语句块之后的代码，不会回到try语句块中。



如果程序中的异常没有被捕获，程序将异常中止。

:::



:::details `异常的示例`

```c++
#include <iostream>
using namespace std;

int main(int argc, char* argv[])
{
    try
    {
        // 可能抛出异常的代码。
        int ii = 0;
        cout << "你是一只什么鸟？（1-傻傻鸟；2-小小鸟）";
        cin >> ii;

        if (ii==1)  throw "不好，有人说我是一只傻傻鸟。";            // throw抛出const char *类型的异常。
        if (ii==2)  throw ii;                                                             // throw抛出int类型的异常。
        if (ii==3)  throw string("不好，有人说我是一只傻傻鸟。"); // throw抛出string类型的异常。

        cout << "我不是一只傻傻鸟，哦耶。\n";
    }
    catch (int ii)
    {
        cout << "异常的类型是int=" << ii << endl;
    }
    catch (const char* ss)
    {
        cout << "异常的类型是const char *=" << ss << endl;
    }
    catch (string str)
    {
        cout << "异常的类型是string=" << str << endl;
    }
    //catch (...)  // 不管什么异常，都在这里处理。
    //{
    //    cout << "捕获到异常，具体没管是什么异常。\n";
    //}

    cout << "程序继续运行......\n";   // 执行完try ... catch ...后，将继续执行程序中其它的代码。
}
```

:::



:::details `栈解旋`

异常被抛出后，从进入try语句块开始，到异常被抛出之前，这期间在栈上构造的所有对象，都会被自动析构。析构的顺序与构造的顺序相反。这一过程称为栈的解旋。

也就是在执行throw前，在try执行期间构造的所有对象被自动析构后，才会进入catch匹配。

在堆上构造的对象肿么办？

:::





:::details `可笑的异常规范`

C++98标准提出了异常规范，目的是为了让使用者知道函数可能会引发哪些异常。

```c
void func1() throw(A, B, C);     // 表示该函数可能会抛出A、B、C类型的异常。
void func2() throw();           // 表示该函数不会抛出异常。
void func3();                  // 该函数不符合C++98的异常规范。
```

C++11标准弃用了异常规范，使用新增的关键字`noexcept`指出函数不会引发异常。

```
void func4() noexcept;         // 该函数不会抛出异常。
```

在实际开发中，大部分程序员懒得在函数后面加`noexcept`，弃用异常已是共识，没必要多此一举。



关键字`noexcept`也可以用作运算符，判断表达试（操作数）是否可能引发异常；如果表达式可能引发异常，则返回false，否则返回true。

:::







:::details  `C++标准库异常`

![](https://blogwnx-bucket.oss-cn-beijing.aliyuncs.com/img/image-20230507184726127-16834564475791.png)

:::

## 重点关注的异常



:::details `std::bad_alloc`

如果内存不足，调用new会产生异常，导致程序中止；如果在new关键字后面加`(std::nothrow)`选项，则返回`nullptr`，不会产生异常。

```c
#include <iostream>
using namespace std;

int main()
{
	try {
		// 如果分配内存失败，会抛出异常。
		//double* ptr = new double[100000000000];  
		// 如果分配内存失败，将返回nullptr，会抛出异常。
		double* ptr = new (std::nothrow) double[100000000000];  

		if (ptr == nullptr) cout << "ptr is null.\n";
	}
	catch (bad_alloc& e)
	{
		cout << "catch bad_alloc.\n";
	}
}
```

:::



:::details `std::bad_cast`

dynamic_cast可以用于引用，但是，C++没有与空指针对应的引用值，如果转换请求不正确，会出现std::bad_cast异常。

:::





:::details `std::bad_typeid`

假设有表达式`typeid(*ptr)`，当`ptr`是空指针时，如果`ptr`是多态的类型，将引发`std::bad_typeid`异常。

:::



## 逻辑错误异常

程序的逻辑错误产生的异常`std::logic_error`，通过合理的编程可以避免。



:::details `std::out_of_range`

```c
Defines a type of object to be thrown as exception. It reports errors that are consequence of attempt to access elements out of defined range.
It may be thrown by the member functions of std::bitset and std::basic_string, by std::stoi and std::stod families of functions, and by the bounds-checked member access functions (e.g. std::vector::at and std::map::at).
```

:::



:::details `std::length_error`

```c
Defines a type of object to be thrown as exception. It reports errors that result from attempts to exceed implementation defined length limits for some object.
This exception is thrown by member functions of std::basic_string and std::vector::reserve.
```

:::



:::details `std::domain_error`

```
Defines a type of object to be thrown as exception. It may be used by the implementation to report domain errors, that is, situations where the inputs are outside of the domain on which an operation is defined.
The standard library components do not throw this exception (mathematical functions report domain errors as specified in math_errhandling). Third-party libraries, however, use this. For example, boost.math throws std::domain_error if boost::math::policies::throw_on_error is enabled (the default setting).
```

:::

:::details `std::invalid_argument`

```
Defines a type of object to be thrown as exception. It reports errors that arise because an argument value has not been accepted.
This exception is thrown by std::bitset::bitset, and the std::stoi and std::stof families of functions.
```

:::

## 其它异常



:::details `std::range_error`

```
Defines a type of object to be thrown as exception. It can be used to report range errors (that is, situations where a result of a computation cannot be represented by the destination type).
The only standard library components that throw this exception are std::wstring_convert::from_bytes and std::wstring_convert::to_bytes.
The mathematical functions in the standard library components do not throw this exception (mathematical functions report range errors as specified in math_errhandling).
```

:::



:::details `std::overflow_error`

```
Defines a type of object to be thrown as exception. It can be used to report arithmetic overflow errors (that is, situations where a result of a computation is too large for the destination type)
The only standard library components that throw this exception are std::bitset::to_ulong and std::bitset::to_ullong.
The mathematical functions of the standard library components do not throw this exception (mathematical functions report overflow errors as specified in math_errhandling). Third-party libraries, however, use this. For example, boost.math throws std::overflow_error if boost::math::policies::throw_on_error is enabled (the default setting).
```

:::



:::details `std_underflow_error`

```
Defines a type of object to be thrown as exception. It may be used to report arithmetic underflow errors (that is, situations where the result of a computation is a subnormal floating-point value)
The standard library components do not throw this exception (mathematical functions report underflow errors as specified in math_errhandling). Third-party libraries, however, use this. For example, boost.math throws std::underflow_error if boost::math::policies::throw_on_error is enabled (the default setting
```

:::



:::details `ios_base::failure`

这个异常，程序员不主动找它就没事。

:::



:::details `std::bad_exception`

```c
This is a special type of exception specifically designed to be listed in the dynamic-exception-specifier of a function (i.e., in its throw specifier).
If a function with bad_exception listed in its dynamic-exception-specifier throws an exception not listed in it and unexpected rethrows it (or throws any other exception also not in the dynamic-exception-specifier), a bad_exception is automatically thrown.
```

:::



## C++断言



:::details `什么是断言？`

断言（assertion）是一种常用的编程手段，用于排除程序中不应该出现的逻辑错误。



使用断言需要包含头文件`<cassert>`或`<assert.h>`，头文件中提供了带参数的宏assert，用于程序在运行时进行断言。

```c
语法：assert(表达式);
```

断言就是判断(表达式)的值，如果为0（false），程序将调用abort()函数中止，如果为非0（true），程序继续执行。

断言可以提高程序的可读性，帮助程序员定位违反了某些前提条件的错误。

注意：

- 断言用于处理程序中不应该发生的错误，而非逻辑上可能会发生的错误。
-  不要把需要执行的代码放到断言的表达式中。
- 断言的代码一般放在函数/成员函数的第一行，表达式多为函数的形参。

:::



:::details `示例:`

```c
#include <iostream>
#include <cassert>              // 断言assert宏需要包含的头文件。
using  namespace std;

void  copydata(void *ptr1,void *ptr2)   // 把ptr2中的数据复制到ptr1中。
{
    assert(ptr1&&ptr2);  // 断言ptr1和ptr2都不会为空。

    cout << "继续执行复制数据的代码......\n";
}

int main()
{
    int ii=0,jj=0;
    
    copydata(&ii, &jj);  // 把ptr2中的数据复制到ptr1中。
}
```

:::



:::details `C++11静态断言`



assert宏是运行时断言，在程序运行的时候才能起作用。

C++11新增了静态断言`static_assert`，用于在编译时检查源代码。

使用静态断言不需要包含头文件。

```c
语法：static_assert(常量表达式,提示信息);
```

注意：static_assert的第一个参数是常量表达式。而assert的表达式既可以是常量，也可以是变量。	

:::

